Workbook

Sheet 总330，8新车
A1: 序号 | B1: 段位 | C1: 等级 | D1: 名称 | E1: 性能分 | F1: 昵称 | G1: 备注
A2: 1 | B2: 青铜 | C2: D | D2: Mitsubishi Lancer Evolution | E2: 1381 | F2: 三菱
A3: 2 | B3: 青铜 | C3: D | D3: BMW Z4 LCI E89 | E3: 1476 | F3: Z4
A4: 3 | B4: 青铜 | C4: D | D4: Chevrolet Camaro LT | E4: 1545 | F4: 大黄蜂
A5: 4 | B5: 青铜 | C5: D | D5: Nissan 370z Nismo | E5: 1662 | F5: 370Z
A6: 5 | B6: 青铜 | C6: D | D6: Dodge Challenger SRT8 | E6: 1683 | F6: 道奇
A7: 6 | B7: 青铜 | C7: D | D7: KTM X-Bow GTX | E7: 1738 | F7: KTM
A8: 7 | B8: 青铜 | C8: D | D8: Volkswagen XL Sport Concept | E8: 1814 | F8: 大众
A9: 8 | B9: 青铜 | C9: D | D9: BMW 3.0 CSL Hommage | E9: 1827 | F9: 宝马-黄
A10: 9 | B10: 青铜 | C10: D | D10: Chevrolet Camaro ZL1 50TH Edition | E10: 1971 | F10: ZL1
A11: 10 | B11: 青铜 | C11: D | D11: DS Automobiles DS E-Tense | E11: 1976 | F11: DS
A12: 11 | B12: 青铜 | C12: D | D12: Porsche Boxster 25th | E12: 1985 | F12: 保时捷-白
A13: 12 | B13: 青铜 | C13: D | D13: Nissan Leaf Nismo RC | E13: 2101 | F13: 遥控车
... A22: 21 | B22: 青铜 | C22: D | D22: Porsche 911 Carrera RS 3.8 | E22: 2435 | F22: 保时捷-黄
A23: 22 | B23: 青铜 | C23: D | D23: Hyundai loniq 5 N | E23: 2559 | F23: 现代5N | G23: 搅屎棍
A24: 23 | B24: 青铜 | C24: C | D24: Porsche 911 Targa 4S | E24: 2571 | F24: 911-蓝
A25: 24 | B25: 青铜 | C25: D | D25: Lotus Emira | E25: 2612 | F25: Emira
A26: 25 | B26: 青铜 | C26: D | D26: Lamborghini Countach 25th Anniversary | E26: 2618 | F26: 老康
A27: 26 | B27: 青铜 | C27: D | D27: Praga R1 | E27: 2624 | F27: R1
A28: 27 | B28: 青铜 | C28: D | D28: Ginetta G60 | E28: 2632 | F28: G60
A29: 28 | B29: 青铜 | C29: C | D29: Bentley Continental GT3 | E29: 2781 | F29: 宾利-绿
A30: 29 | B30: 青铜 | C30: D | D30: Glickenhaus 004C | E30: 2840 | F30: 004C | G30: 滑流能玩
A31: 30 | B31: 青铜 | C31: D | D31: Alfa Romeo Giulia GTam | E31: 2895 | F31: 阿法罗密
A32: 31 | B32: 青铜 | C32: D | D32: Toyota GR Supra Racing Concept | E32: 2930 | F32: Supra
A33: 32 | B33: 青铜 | C33: C | D33: Volkswagen Electric R | E33: 3062 | F33: 电大众 | G33: 搅屎棍
A34: 33 | B34: 青铜 | C34: D | D34: Ford Mustang Mach-E1400 | E34: 3097 | F34: 电马 | G34: 能玩
A35: 34 | B35: 青铜 | C35: B | D35: Kimera EVO37 | E35: 3108 | F35: Evo37 | G35: 综合霸主
A36: 35 | B36: 青铜 | C36: B | D36: Mazda Furai | E36: 3408 | F36: 风籁 | G36: 次霸
A37: 36 | B37: 白银 | C37: C | D37: Lotus Evora Sport 410 | E37: 2123 | F37: 莲花410
A38: 37 | B38: 白银 | C38: C | D38: Porsche 911 GTS Coupe | E38: 2185 | F38: 911-黄
A39: 38 | B39: 白银 | C39: C | D39: Mercedes-Benz AMG GT S | E39: 2281 | F39: AMG GT-黄
A40: 39 | B40: 白银 | C40: C | D40: Aston Martin DB11 | E40: 2330 | F40: BD11-青
A41: 40 | B41: 白银 | C41: C | D41: Porsche 718 Cayman | E41: 2344 | F41: 718
A42: 41 | B42: 白银 | C42: C | D42: Lotus Elise Sprint 220 | E42: 2363 | F42: 小莲花
A43: 42 | B43: 白银 | C43: C | D43: BMW M4 GTS | E43: 2447 | F43: M4-黑
A44: 43 | B44: 白银 | C44: C | D44: Jaguar F-Type SVR | E44: 2487 | F44: 捷豹-红
A45: 44 | B45: 白银 | C45: C | D45: Honda Civic Type-R | E45: 2527 | F45: 思域
A46: 45 | B46: 白银 | C46: C | D46: Exotic Rides W70 | E46: 2633 | F46: W70
A47: 46 | B47: 白银 | C47: C | D47: Rezvani Beast X | E47: 2635 | F47: 野兽
A48: 47 | B48: 白银 | C48: C | D48: TVR Griffith | E48: 2641 | F48: 格里芬斯
...

Sheet 青铜
A1: 段位 | B1: 等级 | C1: 名称 | D1: 性能分 | E1: 昵称 | F1: 备注 | G1: 位置 | H1: 符号 | I1: 优先级
A2: 青铜 | B2: B | C2: Kimera EVO37 | D2: 3108 | E2: Evo37 | F2: 综合霸主 | G2: 34 | H2: , | I2: 1 | J2: =G2&H2 -> 34, | L2: ▶ | M2: =_xlfn.CONCAT(J:J) -> 34,35,33,32,29,22,
A3: 青铜 | B3: B | C3: Mazda Furai | D3: 3408 | E3: 风籁 | F3: 次霸 | G3: 35 | H3: , | I3: 2 | J3: =G3&H3 -> 35,
A4: 青铜 | B4: D | C4: Ford Mustang Mach-E1400 | D4: 3097 | E4: 电马 | F4: 能玩 | G4: 33 | H4: , | I4: 3 | J4: =G4&H4 -> 33,
A5: 青铜 | B5: C | C5: Volkswagen Electric R | D5: 3062 | E5: 电大众 | F5: 搅屎棍 | G5: 32 | H5: , | I5: 4 | J5: =G5&H5 -> 32,
A6: 青铜 | B6: D | C6: Glickenhaus 004C | D6: 2840 | E6: 004C | F6: 滑流能玩 | G6: 29 | H6: , | I6: 5 | J6: =G6&H6 -> 29,
A7: 青铜 | B7: D | C7: Hyundai loniq 5 N | D7: 2559 | E7: 现代5N | F7: 搅屎棍 | G7: 22 | H7: , | I7: 6 | J7: =G7&H7 -> 22,
A8: 青铜 | B8: D | C8: Toyota GR Supra Racing Concept | D8: 2930 | E8: Supra | G8: 31 | H8: ,
A9: 青铜 | B9: D | C9: Alfa Romeo Giulia GTam | D9: 2895 | E9: 阿法罗密 | G9: 30 | H9: ,
A10: 青铜 | B10: C | C10: Bentley Continental GT3 | D10: 2781 | E10: 宾利-绿 | G10: 28 | H10: ,
A11: 青铜 | B11: D | C11: Ginetta G60 | D11: 2632 | E11: G60 | G11: 27 | H11: ,
A12: 青铜 | B12: D | C12: Praga R1 | D12: 2624 | E12: R1 | G12: 26 | H12: ,
A13: 青铜 | B13: D | C13: Lamborghini Countach 25th Anniversary | D13: 2618 | E13: 老康 | G13: 25 | H13: ,
A14: 青铜 | B14: D | C14: Lotus Emira | D14: 2612 | E14: Emira | G14: 24 | H14: ,
A15: 青铜 | B15: C | C15: Porsche 911 Targa 4S | D15: 2571 | E15: 911-蓝 | G15: 23 | H15: ,
A16: 青铜 | B16: D | C16: Porsche 911 Carrera RS 3.8 | D16: 2435 | E16: 保时捷-黄 | G16: 21 | H16: ,
A17: 青铜 | B17: C | C17: Ford Shelby GT350R | D17: 2531 | E17: 野马-蓝 | G17: 20 | H17: ,
A18: 青铜 | B18: D | C18: Lotus Emeya | D18: 2402 | E18: 阿米娅 | G18: 19 | H18: ,
A19: 青铜 | B19: D | C19: Infiniti Project Black S | D19: 2371 | E19: 英菲尼迪 | G19: 18 | H19: ,
... A36: 青铜 | B36: D | C36: Mitsubishi Lancer Evolution | D36: 1381 | E36: 三菱 | G36: 1 | H36: ,

Sheet 白银
A1: 段位 | B1: 等级 | C1: 名称 | D1: 性能分 | E1: 昵称 | F1: 备注 | G1: 位置 | H1: 符号 | I1: 优先级
A2: 白银 | B2: B | C2: Mercedes-Benz Mercedes-AMG GT Black Series | D2: 3513 | E2: 奔驰 | F2: 综合霸主 | G2: 41 | H2: , | I2: 1 | J2: =G2&H2 -> 41, | L2: ▶ | M2: =_xlfn.CONCAT(J:J) -> 41,44,42,40,28,27,43,36,
A3: 白银 | B3: B | C3: Maserati MC20 GT2 | D3: 3832 | E3: MC20 GT2 | F3: 次霸 | G3: 44 | H3: , | I3: 2 | J3: =G3&H3 -> 44,
A4: 白银 | B4: B | C4: Renault R.S. 01 | D4: 3571 | E4: 雷诺-黄 | G4: 42 | H4: , | I4: 3 | J4: =G4&H4 -> 42,
A5: 白银 | B5: B | C5: Bentley Mulliner Bacalar | D5: 3340 | E5: 宾利-黄 | G5: 40 | H5: , | I5: 4 | J5: =G5&H5 -> 40,
A6: 白银 | B6: C | C6: Saleen S1 | D6: 3148 | E6: 赛麟S1 | G6: 28 | H6: , | I6: 5 | J6: =G6&H6 -> 28,
A7: 白银 | B7: C | C7: Nissan 370z Nismo Neon Edition | D7: 3121 | E7: 霓虹370Z | G7: 27 | H7: , | I7: 6 | J7: =G7&H7 -> 27,
A8: 白银 | B8: B | C8: Lamborghini Miura Concept | D8: 3688 | E8: 缪拉 | G8: 43 | H8: , | I8: 7 | J8: =G8&H8 -> 43,
A9: 白银 | B9: B | C9: Lamborghini Huracan Super Trofeo Evo | D9: 3256 | E9: 小小牛 | G9: 36 | H9: , | I9: 8 | J9: =G9&H9 -> 36,
A10: 白银 | B10: B | C10: Lamborghini Huracan STO | D10: 3236 | E10: 牛STO | F10: 搅屎棍 | G10: 34 | H10: ,
A11: 白银 | B11: B | C11: Ferrari Monza SP1 | D11: 3334 | E11: 浴缸 | G11: 39 | H11: ,
A12: 白银 | B12: B | C12: Jaguar XE SV Project 8 | D12: 3289 | E12: 捷豹-蓝 | G12: 38 | H12: ,
A13: 白银 | B13: B | C13: Mercedes-Benz 2022 Showcar Vision AMG | D13: 3288 | E13: 车联奔驰 | G13: 37 | H13: ,
A14: 白银 | B14: B | C14: TVR Sagaris | D14: 3246 | E14: TVR Sagaris | G14: 35 | H14: ,
A15: 白银 | B15: C | C15: Porsche Mission R | D15: 3229 | E15: Mission R | G15: 33 | H15: ,
A16: 白银 | B16: C | C16: Porsche 911 50 Years Porsche Design | D16: 3210 | E16: 911 50周年 | G16: 32 | H16: ,
A17: 白银 | B17: B | C17: Maserati Alfieri | D17: 3209 | E17: 玛莎-银 | G17: 31 | H17: ,
A18: 白银 | B18: B | C18: Aston Martin Valour | D18: 3178 | E18: 马丁-绿 | G18: 30 | H18: ,
A19: 白银 | B19: C | C19: Arash AF10 | D19: 3109 | E19: AF10 | G19: 26 | H19: ,
A20: 白银 | B20: C | C20: Ferrari Roma | D20: 3061 | E20: 罗马 | G20: 25 | H20: ,
A21: 白银 | B21: C | C21: Ford Mustang RTR Spec 5 10th Anniv. | D21: 3025 | E21: 福特RTR | G21: 24 | H21: ,
A22: 白银 | B22: C | C22: Donkervoort D8 GTO | D22: 2991 | E22: 拖拉机 | G22: 23 | H22: ,
... A39: 白银 | B39: C | C39: Lotus Elise Sprint 220 | D39: 2363 | E39: 小莲花 | G39: 6 | H39: ,
A40: 白银 | B40: C | C40: Porsche 718 Cayman | D40: 2344 | E40: 718 | G40: 5 | H40: ,
A41: 白银 | B41: C | C41: Aston Martin DB11 | D41: 2330 | E41: BD11-青 | G41: 4 | H41: ,
A42: 白银 | B42: C | C42: Mercedes-Benz AMG GT S | D42: 2281 | E42: AMG GT-黄 | G42: 3 | H42: ,
A43: 白银 | B43: C | C43: Porsche 911 GTS Coupe | D43: 2185 | E43: 911-黄 | G43: 2 | H43: ,
A44: 白银 | B44: C | C44: Lotus Evora Sport 410 | D44: 2123 | E44: 莲花410 | G44: 1 | H44: ,

Sheet 黄金
A1: 段位 | B1: 等级 | C1: 名称 | D1: 性能分 | E1: 昵称 | F1: 备注 | G1: 位置 | H1: 符号 | I1: 优先级
A2: 黄金 | B2: C | C2: Aston Martin DBS 770 Ultimate | D2: 3922 | E2: 马丁770 | F2: 滑流霸主 | G2: 41 | H2: , | I2: 1 | J2: =G2&H2 -> 41, | L2: ▶ | M2: =_xlfn.CONCAT(J:J) -> 41,39,36,16,45,26,32,25,31,23,42,44,28,10,
A3: 黄金 | B3: B | C3: Lamborghini Diablo GT | D3: 3869 | E3: Diablo | F3: 滑流能玩 | G3: 39 | H3: , | I3: 2 | J3: =G3&H3 -> 39,
A4: 黄金 | B4: B | C4: Bugatti EB110 | D4: 3756 | E4: EB110 | F4: 滑流能玩 | G4: 36 | H4: , | I4: 3 | J4: =G4&H4 -> 36,
A5: 黄金 | B5: B | C5: Dodge Viper GTS | D5: 3295 | E5: 紫蛇 | F5: 滑流不错 | G5: 16 | H5: , | I5: 4 | J5: =G5&H5 -> 16,
A6: 黄金 | B6: C | C6: Nissan Z GT4 | D6: 4098 | E6: GT4 | F6: 综合霸主 | G6: 45 | H6: , | I6: 5 | J6: =G6&H6 -> 45,
A7: 黄金 | B7: B | C7: McLaren GT | D7: 3432 | E7: 迈凯伦GT | F7: 次霸 | G7: 26 | H7: , | I7: 6 | J7: =G7&H7 -> 26,
A8: 黄金 | B8: B | C8: Aston Martin DB12 | D8: 3580 | E8: 马丁-绿 | F8: 综合次霸 | G8: 32 | H8: , | I8: 7 | J8: =G8&H8 -> 32,
A9: 黄金 | B9: B | C9: DS Automobiles DS E-Tense Performance | D9: 3424 | E9: DS王 | F9: 搅屎棍 | G9: 25 | H9: , | I9: 8 | J9: =G9&H9 -> 25,
A10: 黄金 | B10: B | C10: Praga Bohema | D10: 3553 | E10: Bohema-蓝 | F10: 能玩搅屎棍 | G10: 31 | H10: , | I10: 9 | J10: =G10&H10 -> 31,
A11: 黄金 | B11: B | C11: Porsche Panamera Turbo S | D11: 3403 | E11: 帕梅 | F11: 搅屎棍 | G11: 23 | H11: , | I11: 10 | J11: =G11&H11 -> 23,
A12: 黄金 | B12: B | C12: De Tomaso P900 | D12: 3922 | E12: P900 | F12: 能玩 | G12: 42 | H12: , | I12: 11 | J12: =G12&H12 -> 42,
A13: 黄金 | B13: B | C13: Ferrari 296 GTB | D13: 4009 | E13: 296 | F13: 能玩 | G13: 44 | H13: , | I13: 12 | J13: =G13&H13 -> 44,
A14: 黄金 | B14: B | C14: Drako GTE | D14: 3434 | E14: 德拉科 | F14: 能玩 | G14: 28 | H14: , | I14: 13 | J14: =G14&H14 -> 28,
A15: 黄金 | B15: B | C15: Ferrari J50 | D15: 3229 | E15: J50 | F15: 滑流能玩 | G15: 10 | H15: , | I15: 14 | J15: =G15&H15 -> 10,
A16: 黄金 | B16: A | C16: Lamborghini Gallardo LP 560-4 | D16: 3706 | E16: 盖拉多 | G16: 35 | H16: ,
A17: 黄金 | B17: B | C17: Lamborghini Huracan Sterrato | D17: 3995 | E17: 越野牛 | F17: 综合霸主 | G17: 43 | H17: ,
A18: 黄金 | B18: B | C18: Chevrolet Corvette Stingray | D18: 3778 | E18: C8-红 | G18: 38 | H18: ,
A19: 黄金 | B19: B | C19: Mercedes-Benz C63 AMG DTM | D19: 3773 | E19: C63 | G19: 37 | H19: ,
A20: 黄金 | B20: B | C20: Lexus LFA Nurburgring Package | D20: 3612 | E20: LFA | G20: 34 | H20: ,
A21: 黄金 | B21: B | C21: Acura NSX GT3 EVO | D21: 3595 | E21: 讴歌-白 | G21: 33 | H21: ,
A22: 黄金 | B22: B | C22: Porsche 911 GT3 R Rennsport | D22: 3546 | E22: 911GT3 | G22: 30 | H22: ,
A23: 黄金 | B23: C | C23: Dodge Charger SRT Hellcat Redeye Widebody | D23: 3518 | E23: 地狱猫 | G23: 29 | H23: ,
A24: 黄金 | B24: B | C24: Ferrari 599XX EVO | D24: 3433 | E24: 599 | G24: 27 | H24: ,
A25: 黄金 | B25: B | C25: Porsche 718 Cayman GT4 Clubsport | D25: 3415 | E25: 718-赛道 | G25: 24 | H25: ,
A26: 黄金 | B26: B | C26: Kepler Motion | D26: 3393 | E26: 开普勒 | G26: 22 | H26: ,
A27: 黄金 | B27: B | C27: ATS Automobili Corsa RRTurbo | D27: 3389 | E27: 鼻炎 | G27: 21 | H27: ,
A28: 黄金 | B28: B | C28: Ares S1 | D28: 3377 | E28: 战神S1 | G28: 20 | H28: ,
A29: 黄金 | B29: B | C29: Ferrari F40 | D29: 3343 | E29: F40 | G29: 19 | H29: ,
A30: 黄金 | B30: B | C30: Ferrari 488 GTB | D30: 3334 | E30: 488 | G30: 18 | H30: ,
A31: 黄金 | B31: B | C31: Italdesign Zerouno | D31: 3295 | E31: 假牛 | G31: 17 | H31: ,
A32: 黄金 | B32: B | C32: Vencer Sarthe | D32: 3290 | E32: 剃刀 | G32: 15 | H32: ,
A33: 黄金 | B33: B | C33: Arash AF8 Falcon Edition | D33: 3289 | E33: AF8 | G33: 14 | H33: ,
A34: 黄金 | B34: B | C34: McLaren Artura | D34: 3280 | E34: 迈凯伦-绿 | G34: 13 | H34: ,
A35: 黄金 | B35: B | C35: Toyota GR Supra 2023 | D35: 3258 | E35: 速霸2023 | G35: 12 | H35: ,
A36: 黄金 | B36: B | C36: Jaguar XJR-15 | D36: 3244 | E36: XJR-15 | G36: 11 | H36: ,
A37: 黄金 | B37: B | C37: Acura 2017 NSX | D37: 3208 | E37: 讴歌-红 | G37: 9 | H37: ,
A38: 黄金 | B38: B | C38: Maserati MC12 | D38: 3100 | E38: MC12 | G38: 8 | H38: ,
A39: 黄金 | B39: B | C39: Artega Scalo SuperErelletra | D39: 3093 | E39: 斯卡洛 | G39: 7 | H39: ,
A40: 黄金 | B40: B | C40: Mercedes-Benz CLK-GTR | D40: 3083 | E40: CLK | G40: 6 | H40: ,
...

Sheet 白金
A1: 段位 | B1: 等级 | C1: 名称 | D1: 性能分 | E1: 昵称 | F1: 备注 | G1: 位置 | H1: 符号 | I1: 优先级
A2: 白金 | B2: A | C2: Citroen GT by Citroen | D2: 4099 | E2: 雪铁龙 | F2: 滑流霸主 | G2: 39 | H2: , | I2: 1 | J2: =G2&H2 -> 39, | L2: ▶ | M2: =_xlfn.CONCAT(J:J) -> 39,40,41,22,34,31,37,28,36,24,23,17,5,4,33,
A3: 白金 | B3: B | C3: FV Frangivento GT65 | D3: 4127 | E3: FV GT65 | F3: 滑流不错 | G3: 40 | H3: , | I3: 2 | J3: =G3&H3 -> 40,
A4: 白金 | B4: A | C4: Pagani Zonda R | D4: 4164 | E4: Zonda R | F4: 滑流不错 | G4: 41 | H4: , | I4: 3 | J4: =G4&H4 -> 41,
A5: 白金 | B5: A | C5: VLF Force 1 V10 | D5: 3929 | E5: 1 V10 | F5: 滑流不错 | G5: 22 | H5: , | I5: 4 | J5: =G5&H5 -> 22,
A6: 白金 | B6: B | C6: Puritalia Berlinetta | D6: 4061 | E6: 巴林塔 | F6: 综合霸主 | G6: 34 | H6: , | I6: 5 | J6: =G6&H6 -> 34,
A7: 白金 | B7: A | C7: Ferrari Enzo Ferrari | D7: 4014 | E7: 恩佐 | F7: 滑流不错 | G7: 31 | H7: , | I7: 6 | J7: =G7&H7 -> 31,
A8: 白金 | B8: B | C8: Lamborghini Invencible | D8: 4091 | E8: 无敌牛 | F8: 搅屎棍 | G8: 37 | H8: , | I8: 7 | J8: =G8&H8 -> 37,
A9: 白金 | B9: B | C9: Lamborghini Reventon Roadster | D9: 3983 | E9: 雷文顿 | G9: 28 | H9: , | I9: 7 | J9: =G9&H9 -> 28,
A10: 白金 | B10: B | C10: Toyota GR Super Sport Concept | D10: 4076 | E10: 丰田GR | G10: 36 | H10: , | I10: 8 | J10: =G10&H10 -> 36,
A11: 白金 | B11: B | C11: Apollo IE | D11: 3946 | E11: Apollo IE | F11: 搅屎棍 | G11: 24 | H11: , | I11: 9 | J11: =G11&H11 -> 24,
A12: 白金 | B12: A | C12: Ferrari 812 Superfast | D12: 3941 | E12: 812 | F12: 能玩 | G12: 23 | H12: , | I12: 10 | J12: =G12&H12 -> 23,
A13: 白金 | B13: B | C13: Aston Martin One77 | D13: 3771 | E13: One77 | F13: 滑流不错 | G13: 17 | H13: , | I13: 11 | J13: =G13&H13 -> 17,
A14: 白金 | B14: B | C14: Aston Martin DBS Superleggera | D14: 3423 | E14: DBS | F14: 综合次霸 | G14: 5 | H14: , | I14: 12 | J14: =G14&H14 -> 5,
A15: 白金 | B15: B | C15: Mercedes-Benz SLR McLaren | D15: 3389 | E15: SLR | F15: 能玩 | G15: 4 | H15: , | I15: 13 | J15: =G15&H15 -> 4,
A16: 白金 | B16: B | C16: Lamborghini Essenza SCV12 | D16: 4036 | E16: SCV12 | F16: 能玩搅屎棍 | G16: 33 | H16: , | I16: 15 | J16: =G16&H16 -> 33,
A17: 白金 | B17: B | C17: Lamborghini SC63 | D17: 4062 | E17: 牛-绿赛道 | F17: 能玩 | G17: 35 | H17: ,
A18: 白金 | B18: B | C18: Formula E Gen 2 Asphalt Edition | D18: 4019 | E18: FE2 | F18: 能玩 | G18: 32 | H18: ,
A19: 白金 | B19: A | C19: Ferrari 488 Challenge EVO | D19: 4095 | E19: 488 | F19: 综合霸主 | G19: 38 | H19: ,
A20: 白金 | B20: A | C20: Porsche Carrera GT | D20: 4010 | E20: Carrera GT | G20: 30 | H20: ,
A21: 白金 | B21: B | C21: McLaren 750S Coupe | D21: 3995 | E21: 750S | G21: 29 | H21: ,
A22: 白金 | B22: B | C22: Aston Martin Vantage GT12 | D22: 3958 | E22: 马丁-白 | G22: 27 | H22: ,
A23: 白金 | B23: B | C23: Ferrari F12 Berlinetta | D23: 3950 | E23: F12红 | G23: 26 | H23: ,
A24: 白金 | B24: B | C24: Sin R1 550 | D24: 3950 | E24: Sin | G24: 25 | H24: ,
A25: 白金 | B25: B | C25: Chevrolet Corvette Grand Sport | D25: 3906 | E25: 五菱-蓝 | G25: 21 | H25: ,
A26: 白金 | B26: B | C26: Lego Technic BMW M4 GT3 EVO | D26: 3895 | E26: 乐高M4 | G26: 20 | H26: ,
A27: 白金 | B27: B | C27: Lamborghini Autentica | D27: 3884 | E27: 牛-灰 | G27: 19 | H27: ,
A28: 白金 | B28: B | C28: Maserati MC20 | D28: 3773 | E28: MC20 | G28: 18 | H28: ,
A29: 白金 | B29: B | C29: Ferrari F12tdf | D29: 3705 | E29: TDF | G29: 16 | H29: ,
A30: 白金 | B30: B | C30: Pagani Zonda HP Barchetta | D30: 3678 | E30: Zonda-蓝 | G30: 15 | H30: ,
A31: 白金 | B31: B | C31: BMW M4 GT3 | D31: 3655 | E31: M4-赛道 | G31: 14 | H31: ,
... A42: 白金 | B42: B | C42: Nissan GT-R Nismo | D42: 3144 | E42: GTR | G42: 1 | H42: ,

Sheet 翡翠
A1: 段位 | B1: 等级 | C1: 名称 | D1: 性能分 | E1: 昵称 | F1: 备注 | G1: 位置 | H1: 符号 | I1: 优先级
A2: 翡翠 | B2: B | C2: Lotus E-R9 | D2: 4308 | E2: E-R9 | F2: 综合霸主 | G2: 31 | H2: , | I2: 1 | J2: =G2&H2 -> 31, | L2: ▶ | M2: =_xlfn.CONCAT(J:J) -> 31,32,33,17,30,29,26,22,20,16,15,14,13,12,
A3: 翡翠 | B3: B | C3: Lamborghini Revuelto | D3: 4375 | E3: 雷文托 | F3: 次霸 | G3: 32 | H3: , | I3: 2 | J3: =G3&H3 -> 32,
A4: 翡翠 | B4: S | C4: Lotus Evija | D4: 4432 | E4: 电莲花 | F4: 次霸 | G4: 33 | H4: , | I4: 3 | J4: =G4&H4 -> 33,
A5: 翡翠 | B5: B | C5: Lamborghini SC18 | D5: 4079 | E5: SC18 | F5: 综合次霸 | G5: 17 | H5: , | I5: 4 | J5: =G5&H5 -> 17,
A6: 翡翠 | B6: B | C6: Apollo EVO | D6: 4265 | E6: 阿波罗 | F6: 能玩 | G6: 30 | H6: , | I6: 5 | J6: =G6&H6 -> 30,
A7: 翡翠 | B7: A | C7: Lego Technic Lamborghini Revuelto | D7: 4264 | E7: 乐高雷文托 | G7: 29 | H7: , | I7: 6 | J7: =G7&H7 -> 29,
A8: 翡翠 | B8: B | C8: Lamborghini Sesto Elemento | D8: 4183 | E8: 第六元素 | F8: 能玩 | G8: 26 | H8: , | I8: 7 | J8: =G8&H8 -> 26,
A9: 翡翠 | B9: S | C9: Porsche 918 Spyder | D9: 4114 | E9: 918 | F9: 能玩 | G9: 22 | H9: , | I9: 8 | J9: =G9&H9 -> 22,
A10: 翡翠 | B10: A | C10: Pagani Zonda Cinque | D10: 4105 | E10: 青葵 | F10: 综合霸主 | G10: 20 | H10: , | I10: 9 | J10: =G10&H10 -> 20,
A11: 翡翠 | B11: B | C11: McLaren Solus GT | D11: 4075 | E11: SGT | G11: 16 | H11: , | I11: 10 | J11: =G11&H11 -> 16,
A12: 翡翠 | B12: B | C12: McLaren 600LT Spider | D12: 4075 | E12: 600LT | G12: 15 | H12: , | I12: 11 | J12: =G12&H12 -> 15,
A13: 翡翠 | B13: B | C13: Aston Martin V12 Vantage 2022 | D13: 4072 | E13: V12 2022 | G13: 14 | H13: , | I13: 12 | J13: =G13&H13 -> 14,
A14: 翡翠 | B14: B | C14: BMW M Hybrid V8 | D14: 4057 | E14: 宝马V8 | G14: 13 | H14: , | I14: 13 | J14: =G14&H14 -> 13,
A15: 翡翠 | B15: A | C15: Chevrolet Corvette ZR1 | D15: 4031 | E15: 五菱-橘 | G15: 12 | H15: , | I15: 14 | J15: =G15&H15 -> 12,
A16: 翡翠 | B16: B | C16: Ford GT MK IV | D16: 4262 | E16: MK4 | G16: 28 | H16: ,
A17: 翡翠 | B17: A | C17: Pagani Huayra R | D17: 4259 | E17: 花雅R | F17: 滑流能玩 | G17: 27 | H17: ,
A18: 翡翠 | B18: B | C18: McLaren Sabre | D18: 4173 | E18: 军刀 | F18: 次霸 | G18: 25 | H18: ,
A19: 翡翠 | B19: A | C19: ATS Automobili GT | D19: 4161 | E19: ATS GT | F19: 滑流不错 | G19: 24 | H19: ,
A20: 翡翠 | B20: A | C20: Automobili Pininfarina Battista Edizione Nino Farina | D20: 4125 | E20: 红秋王 | F20: 能玩 | G20: 23 | H20: ,
A21: 翡翠 | B21: B | C21: Lamborghini Huracan EVO Spyder | D21: 4108 | E21: 小牛 | G21: 21 | H21: ,
A22: 翡翠 | B22: A | C22: Lamborghini Aventador SVJ Roadster | D22: 4080 | E22: SVJ | F22: 综合霸主 | G22: 18 | H22: ,
A23: 翡翠 | B23: A | C23: McLaren Senna GTR | D23: 4025 | E23: Senna GTR | G23: 11 | H23: ,
A24: 翡翠 | B24: A | C24: Mcmurtry Speirling | D24: 4003 | E24: 小风扇 | F24: 超级搅屎棍 | G24: 10 | H24: ,
A25: 翡翠 | B25: A | C25: Lamborghini Murcielago LP 640Roadster | D25: 3924 | E25: 蝙蝠 | G25: 9 | H25: ,
A26: 翡翠 | B26: A | C26: Apex AP-0 | D26: 3922 | E26: APEX | G26: 8 | H26: ,
A27: 翡翠 | B27: A | C27: Lego Technic McLaren Senna GTR | D27: 3846 | E27: 乐高SennaGTR | G27: 7 | H27: ,
A28: 翡翠 | B28: A | C28: Ferrari FXX K | D28: 3821 | E28: FXXK | G28: 6 | H28: ,
A29: 翡翠 | B29: A | C29: Lamborghini Aventador SV Coupe | D29: 3763 | E29: 丹尼车 | G29: 5 | H29: ,
A30: 翡翠 | B30: A | C30: Lamborghini Centenario | D30: 3696 | E30: 百年牛 | G30: 4 | H30: ,
A31: 翡翠 | B31: A | C31: McLaren P1 | D31: 3602 | E31: P1 | G31: 3 | H31: ,
A32: 翡翠 | B32: A | C32: Apollo N | D32: 3548 | E32: 阿波罗N | G32: 2 | H32: ,
A33: 翡翠 | B33: A | C33: Lego Technic Ferrari FXX K | D33: 3522 | E33: 乐高马王 | G33: 1 | H33: ,

Sheet 钻石
A1: 段位 | B1: 等级 | C1: 名称 | D1: 性能分 | E1: 昵称 | F1: 备注 | G1: 位置 | H1: 符号 | I1: 优先级
A2: 钻石 | B2: S | C2: W Motors Fenyr Supersport | D2: 4479 | E2: 狼王 | F2: 滑流霸主 | G2: 43 | H2: , | I2: 1 | J2: =G2&H2 -> 43, | L2: ▶ | M2: =_xlfn.CONCAT(J:J) -> 43,50,40,48,45,49,27,23,17,15,7,42,18,6,5,39,24,35,31,22,30,13,3,46,28,
A3: 钻石 | B3: A | C3: Mercedes-Benz Vision One-Eleven | D3: 4600 | E3: 111 | F3: 综合霸主 | G3: 50 | H3: , | I3: 2 | J3: =G3&H3 -> 50,
A4: 钻石 | B4: A | C4: Jaguar XJR-9 | D4: 4438 | E4: 小金人 | F4: 滑流能玩 | G4: 40 | H4: , | I4: 3 | J4: =G4&H4 -> 40,
A5: 钻石 | B5: A | C5: Ferrari 499P Modificata | D5: 4572 | E5: 499 | F5: 搅屎棍 | G5: 48 | H5: , | I5: 4 | J5: =G5&H5 -> 48,
A6: 钻石 | B6: A | C6: Aston Martin Valhalla Concept Car | D6: 4515 | E6: 英灵殿 | F6: 次霸 | G6: 45 | H6: , | I6: 5 | J6: =G6&H6 -> 45,
A7: 钻石 | B7: A | C7: De Tomaso P72 | D7: 4586 | E7: P72 | F7: 能玩 | G7: 49 | H7: , | I7: 6 | J7: =G7&H7 -> 49,
A8: 钻石 | B8: A | C8: Mclaren F1 LM | D8: 4301 | E8: F1LM | F8: 滑流能玩 | G8: 27 | H8: , | I8: 7 | J8: =G8&H8 -> 27,
A9: 钻石 | B9: A | C9: Porsche 911 GT2 RS ClubSport | D9: 4289 | E9: 蛙王 | G9: 23 | H9: , | I9: 8 | J9: =G9&H9 -> 23,
A10: 钻石 | B10: A | C10: Glickenhaus 007S | D10: 4192 | E10: 007S | F10: 能玩 | G10: 17 | H10: , | I10: 9 | J10: =G10&H10 -> 17,
A11: 钻石 | B11: A | C11: Peugeot 9X8 | D11: 4172 | E11: 9x8 | F11: 搅屎棍 | G11: 15 | H11: , | I11: 10 | J11: =G11&H11 -> 15,
A12: 钻石 | B12: A | C12: Peugeot Onyx | D12: 4026 | E12: 大狮子 | G12: 7 | H12: , | I12: 11 | J12: =G12&H12 -> 7,
A13: 钻石 | B13: A | C13: Noble M600 Speedster | D13: 4454 | E13: M600 | F13: 次霸 | G13: 42 | H13: , | I13: 12 | J13: =G13&H13 -> 42,
A14: 钻石 | B14: A | C14: Nissan GT-R Neon Edition | D14: 4201 | E14: 霓虹GTR | F14: 搅屎棍 | G14: 18 | H14: , | I14: 13 | J14: =G14&H14 -> 18,
A15: 钻石 | B15: A | C15: TechRules AT96 Track Version | D15: 4020 | E15: AT96 | F15: 能玩 | G15: 6 | H15: , | I15: 14 | J15: =G15&H15 -> 6,
A16: 钻石 | B16: A | C16: Porsche 911 GT3 RS | D16: 4019 | E16: 绿蛙 | G16: 5 | H16: , | I16: 15 | J16: =G16&H16 -> 5,
A17: 钻石 | B17: S | C17: Lamborghini Terzo Millennio | D17: 4400 | E17: 电牛 | F17: 次霸 | G17: 39 | H17: , | I17: 16 | J17: =G17&H17 -> 39,
A18: 钻石 | B18: A | C18: Ferrari SF90 XX Stradale | D18: 4286 | E18: F90 XX | G18: 24 | H18: , | I18: 17 | J18: =G18&H18 -> 24,
A19: 钻石 | B19: A | C19: FV Frangivento Asfane | D19: 4377 | E19: 鼠标 | F19: 次霸 | G19: 35 | H19: , | I19: 18 | J19: =G19&H19 -> 35,
A20: 钻石 | B20: S | C20: Lamborghini SC20 | D20: 4326 | E20: SC20 | G20: 31 | H20: , | I20: 19 | J20: =G20&H20 -> 31,
A21: 钻石 | B21: A | C21: McLaren 650S GT3 | D21: 4266 | E21: 650S | F21: 能玩 | G21: 22 | H21: , | I21: 20 | J21: =G21&H21 -> 22,
A22: 钻石 | B22: A | C22: Genty Akylone | D22: 4323 | E22: AK龙 | G22: 30 | H22: , | I22: 21 | J22: =G22&H22 -> 30,
A23: 钻石 | B23: A | C23: McLaren 570S Spider | D23: 4135 | E23: 570S | G23: 13 | H23: , | I23: 22 | J23: =G23&H23 -> 13,
A24: 钻石 | B24: A | C24: Icona Vulcano Titanium | D24: 3957 | E24: 火山 | F24: 能玩 | G24: 3 | H24: , | I24: 23 | J24: =G24&H24 -> 3,
A25: 钻石 | B25: A | C25: Lexus Electrified Sport Concept | D25: 4565 | E25: 雷萨车联 | G25: 46 | H25: , | I25: 24 | J25: =G25&H25 -> 46,
A26: 钻石 | B26: A | C26: Zenvo TSR-S | D26: 4301 | E26: 小自燃 | G26: 28 | H26: , | I26: 25 | J26: =G26&H26 -> 28,
A27: 钻石 | B27: A | C27: Zenvo Aurora Agil | D27: 4393 | E27: 阿giao | F27: 次霸 | G27: 37 | H27: ,
A28: 钻石 | B28: A | C28: Nissan GTR-50 Italdesign | D28: 4127 | E28: 电动GTR | G28: 12 | H28: ,
A29: 钻石 | B29: A | C29: Porsche 935(2019) | D29: 4229 | E29: 935 | G29: 20 | H29: ,
A30: 钻石 | B30: S | C30: Vision 1789 | D30: 4442 | E30: 1789 | F30: 次霸 | G30: 41 | H30: ,
A31: 钻石 | B31: A | C31: Porsche 919 Street | D31: 4628 | E31: 919 | F31: 综合霸主 | G31: 52 | H31: ,
A32: 钻石 | B32: A | C32: Automobili Pininfarina B95 | D32: 4605 | E32: 新秋王 | G32: 51 | H32: ,
A33: 钻石 | B33: A | C33: Mercedes-Benz Merceds-AMG One | D33: 4571 | E33: AMG ONE | F33: 次霸 | G33: 47 | H33: ,
A34: 钻石 | B34: A | C34: Rimac Concept One | D34: 4490 | E34: C1 | F34: 搅屎棍 | G34: 44 | H34: ,
A35: 钻石 | B35: A | C35: FV Frangivento Sorpasso GT3 | D35: 4398 | E35: FV GT3 | F35: 能玩 | G35: 38 | H35: ,
A36: 钻石 | B36: A | C36: Spania GTA 2015 GTA Spano | D36: 4385 | E36: 西班牙 | G36: 36 | H36: ,
A37: 钻石 | B37: A | C37: Lamborghini Temerario | D37: 4372 | E37: T牛 | G37: 34 | H37: ,
A38: 钻石 | B38: A | C38: Ford Shelby Super Snake | D38: 4350 | E38: 超级蛇 | G38: 33 | H38: ,
A39: 钻石 | B39: A | C39: Volkswagen W12 Coupe | D39: 4334 | E39: W12 | G39: 32 | H39: ,
A40: 钻石 | B40: A | C40: Pagani Utopia Coupe | D40: 4308 | E40: 乌托邦 | F40: 能玩 | G40: 29 | H40: ,
...

Sheet 精英
A1: 段位 | B1: 等级 | C1: 名称 | D1: 性能分 | E1: 昵称 | F1: 备注 | G1: 位置 | H1: 符号 | I1: 优先级
A2: 精英 | B2: S | C2: Lamborghini Sian FKP 37 | D2: 4860 | E2: 西安 | F2: 次霸搅屎棍 | G2: 37 | H2: , | I2: 1 | J2: =G2&H2 -> 37, | L2: ▶ | M2: =_xlfn.CONCAT(J:J) -> 37,25,34,14,33,36,13,38,11,31,29,30,9,26,6,19,18,17,16,20,10,7,5,2,12,
A3: 精英 | B3: S | C3: Saleen S7 Twin Turbo | D3: 4629 | E3: 赛麟S7 | F3: 滑流能玩 | G3: 25 | H3: , | I3: 2 | J3: =G3&H3 -> 25,
A4: 精英 | B4: S | C4: Tushek TS 900 Racer Pro | D4: 4782 | E4: TS 900 | F4: 次霸搅屎棍 | G4: 34 | H4: , | I4: 3 | J4: =G4&H4 -> 34,
A5: 精英 | B5: S | C5: Automobili Pininfarina Battista | D5: 4551 | E5: 秋王 | F5: 搅屎棍 | G5: 14 | H5: , | I5: 4 | J5: =G5&H5 -> 14,
A6: 精英 | B6: S | C6: Lego Technic Bugatti Chiron Pur Sport | D6: 4764 | E6: 乐高PS龙 | F6: 能玩 | G6: 33 | H6: , | I6: 5 | J6: =G6&H6 -> 33,
A7: 精英 | B7: S | C7: Bugatti Chiron Pur Sport | D7: 4821 | E7: PS龙 | F7: 霸主搅屎棍 | G7: 36 | H7: , | I7: 6 | J7: =G7&H7 -> 36,
A8: 精英 | B8: S | C8: Ferrari SF90 Stradale | D8: 4550 | E8: SF90 | F8: 搅屎棍 | G8: 13 | H8: , | I8: 7 | J8: =G8&H8 -> 13,
A9: 精英 | B9: S | C9: HTT Locus Plethore LC750 | D9: 4955 | E9: 胡图图 | F9: 综合霸主 | G9: 38 | H9: , | I9: 8 | J9: =G9&H9 -> 38,
A10: 精英 | B10: S | C10: Zenvo TS1 GT Anniversary | D10: 4521 | E10: 自燃王 | F10: 综合次霸 | G10: 11 | H10: , | I10: 9 | J10: =G10&H10 -> 11,
A11: 精英 | B11: S | C11: Ford Team Fordzilla P1 | D11: 4709 | E11: FP1 | F11: 搅屎棍 | G11: 31 | H11: , | I11: 10 | J11: =G11&H11 -> 31,
A12: 精英 | B12: S | C12: Ford Mustang RTR Spec 5-FD | D12: 4693 | E12: 福特S RTR | F12: 能玩 | G12: 29 | H12: , | I12: 11 | J12: =G12&H12 -> 29,
A13: 精英 | B13: S | C13: Ajlani Drakuma | D13: 4702 | E13: 中东狼 | F13: 滑流霸主 | G13: 30 | H13: , | I13: 12 | J13: =G13&H13 -> 30,
A14: 精英 | B14: S | C14: Aston Martin Valkyrie | D14: 4487 | E14: 女武神 | G14: 9 | H14: , | I14: 13 | J14: =G14&H14 -> 9,
A15: 精英 | B15: S | C15: W Motors Lykan Hypersport Neon Edition | D15: 4636 | E15: 霓虹狼 | F15: 综合次霸 | G15: 26 | H15: , | I15: 14 | J15: =G15&H15 -> 26,
A16: 精英 | B16: S | C16: McLaren Senna | D16: 4407 | E16: 塞纳 | G16: 6 | H16: , | I16: 15 | J16: =G16&H16 -> 6,
A17: 精英 | B17: S | C17: Lamborghini Countach LPI 800-4 | D17: 4571 | E17: 新康 | G17: 19 | H17: , | I17: 16 | J17: =G17&H17 -> 19,
A18: 精英 | B18: S | C18: Nio EP9 | D18: 4571 | E18: EP9 | G18: 18 | H18: , | I18: 17 | J18: =G18&H18 -> 18,
A19: 精英 | B19: S | C19: Naran Hyper Coupe | D19: 4564 | E19: 纳兰 | G19: 17 | H19: , | I19: 18 | J19: =G19&H19 -> 17,
A20: 精英 | B20: S | C20: Pagani Imola | D20: 4564 | E20: 伊莫拉 | G20: 16 | H20: , | I20: 19 | J20: =G20&H20 -> 16,
A21: 精英 | B21: S | C21: Hyundai N Vision 74 | D21: 4579 | E21: 现代74 | G21: 20 | H21: , | I21: 20 | J21: =G21&H21 -> 20,
A22: 精英 | B22: S | C22: Mercedes-Benz C11 | D22: 4506 | E22: C11 | F22: 综合次霸 | G22: 10 | H22: , | I22: 21 | J22: =G22&H22 -> 10,
A23: 精英 | B23: S | C23: Bugatti Veyron 16.4 Grand Sport Vitesse | D23: 4411 | E23: 16.4 | G23: 7 | H23: , | I23: 22 | J23: =G23&H23 -> 7,
A24: 精英 | B24: S | C24: Ferrari F8 Tributo | D24: 4313 | E24: F8 | G24: 5 | H24: , | I24: 23 | J24: =G24&H24 -> 5,
A25: 精英 | B25: S | C25: Vanda Electrics Dendrobium | D25: 4124 | E25: 万达 | G25: 2 | H25: , | I25: 24 | J25: =G25&H25 -> 2,
A26: 精英 | B26: S | C26: Rimac Concept S | D26: 4528 | E26: CS | F26: 搅屎棍 | G26: 12 | H26: , | I26: 25 | J26: =G26&H26 -> 12,
A27: 精英 | B27: S | C27: W Motors Lykan Hypersport | D27: 4083 | E27: 狼崽 | F27: 滑流能玩 | G27: 1 | H27: ,
A28: 精英 | B28: S | C28: Chrysler ME412 | D28: 4241 | E28: ME412 | G28: 3 | H28: ,
A29: 精英 | B29: S | C29: Porsche 918 Spyder Asphalt Edition | D29: 4252 | E29: 918投票 | G29: 4 | H29: ,
A30: 精英 | B30: S | C30: Pininfarina Teorema | D30: 4473 | E30: 宾法面包 | G30: 8 | H30: ,
A31: 精英 | B31: S | C31: TechRules AT96 Dragon Boat Edition | D31: 4556 | E31: 腾风龙舟 | G31: 15 | H31: ,
A32: 精英 | B32: S | C32: Faraday Future FFZero1 | D32: 4602 | E32: 法拉第 | F32: 滑流能玩 | G32: 21 | H32: ,
A33: 精英 | B33: S | C33: Bugatti Divo | D33: 4607 | E33: Divo | F33: 能玩 | G33: 22 | H33: ,
A34: 精英 | B34: S | C34: Porsche GT3 RS 2023 | D34: 4621 | E34: 保时捷2023 | G34: 23 | H34: ,
A35: 精英 | B35: S | C35: Arash Imperium | D35: 4623 | E35: 帝国 | F35: 综合次霸 | G35: 24 | H35: ,
A36: 精英 | B36: S | C36: W Motors Fenyr Super Sport CNYEdition | D36: 4653 | E36: 春节狼王 | F36: 综合次霸 | G36: 27 | H36: ,
A37: 精英 | B37: S | C37: Zenvo TSR-S Dragon Boat Edition | D37: 4665 | E37: 龙舟自燃 | G37: 28 | H37: ,
A38: 精英 | B38: S | C38: Torino Design Super Sport | D38: 4741 | E38: 都灵 | F38: 滑流能玩 | G38: 32 | H38: ,
A39: 精英 | B39: S | C39: Porsche 917 Living Legend | D39: 4791 | E39: 917 | F39: 能玩 | G39: 35 | H39: ,

Sheet 宗师
A1: 段位 | B1: 等级 | C1: 名称 | D1: 性能分 | E1: 昵称 | F1: 备注 | G1: 位置 | H1: 符号 | I1: 优先级
A2: 宗师 | B2: S | C2: Czinger 21C | D2: 5149 | E2: 21C | F2: 搅屎棍 | G2: 23 | H2: , | I2: 1 | J2: =G2&H2 -> 23, | L2: ▶ | M2: =_xlfn.CONCAT(J:J) -> 23,21,19,14,10,13,12,7,15,16,3,2,1,4,
A3: 宗师 | B3: S | C3: Koenigsegg Gemera | D3: 5085 | E3: 杰弟 | F3: 搅屎棍 | G3: 21 | H3: , | I3: 2 | J3: =G3&H3 -> 21,
A4: 宗师 | B4: S | C4: Koenigsegg One:1 | D4: 5056 | E4: 旺旺 | F4: 次霸 | G4: 19 | H4: , | I4: 3 | J4: =G4&H4 -> 19,
A5: 宗师 | B5: S | C5: Rimac Nevera | D5: 4897 | E5: 兔子 | F5: 能玩 | G5: 14 | H5: , | I5: 4 | J5: =G5&H5 -> 14,
A6: 宗师 | B6: S | C6: Bugatti Centodieci | D6: 4843 | E6: 白龙 | F6: 能玩搅屎棍 | G6: 10 | H6: , | I6: 4 | J6: =G6&H6 -> 10,
A7: 宗师 | B7: S | C7: Raesr Aglaia | D7: 4887 | E7: 中光速 | F7: 能玩 | G7: 13 | H7: , | I7: 5 | J7: =G7&H7 -> 13,
A8: 宗师 | B8: S | C8: Icona Vulcano Spyder | D8: 4868 | E8: 冰山 | F8: 能玩 | G8: 12 | H8: , | I8: 6 | J8: =G8&H8 -> 12,
A9: 宗师 | B9: S | C9: BXR Bailey Blade GT1 | D9: 4759 | E9: 鞋拔子 | F9: 能玩 | G9: 7 | H9: , | I9: 6 | J9: =G9&H9 -> 7,
A10: 宗师 | B10: S | C10: Hennessey Venom GT | D10: 4963 | E10: 毒药GT | F10: 综合霸主 | G10: 15 | H10: , | I10: 7 | J10: =G10&H10 -> 15,
A11: 宗师 | B11: S | C11: Koenigsegg CCXR | D11: 4998 | E11: CCXR | G11: 16 | H11: , | I11: 8 | J11: =G11&H11 -> 16,
A12: 宗师 | B12: S | C12: Koenigsegg Regera | D12: 4616 | E12: 统治 | F12: 能玩 | G12: 3 | H12: , | I12: 8 | J12: =G12&H12 -> 3,
A13: 宗师 | B13: S | C13: McLaren Speedtail | D13: 4590 | E13: 速尾 | G13: 2 | H13: , | I13: 9 | J13: =G13&H13 -> 2,
A14: 宗师 | B14: S | C14: Trion Nemesis | D14: 4344 | E14: 复仇 | F14: 能玩 | G14: 1 | H14: , | I14: 10 | J14: =G14&H14 -> 1,
A15: 宗师 | B15: S | C15: Ultima RS | D15: 4650 | E15: 奥特曼 | G15: 4 | H15: , | I15: 11 | J15: =G15&H15 -> 4,
A16: 宗师 | B16: S | C16: Raesr Tartarus | D16: 5355 | E16: 焯光速 | F16: 滑流霸主 | G16: 24 | H16: ,
A17: 宗师 | B17: S | C17: Bugatti Mistral | D17: 5096 | E17: 风龙 | F17: 次霸 | G17: 22 | H17: ,
A18: 宗师 | B18: S | C18: Deus Vayanne | D18: 5082 | E18: 冬王 | F18: 能玩 | G18: 20 | H18: ,
A19: 宗师 | B19: S | C19: Bugatti La Voiture Noire | D19: 5055 | E19: 黑龙 | F19: 综合次霸 | G19: 18 | H19: ,
A20: 宗师 | B20: S | C20: Nilu27 | D20: 5003 | E20: 尼禄 | G20: 17 | H20: ,
A21: 宗师 | B21: S | C21: Aspark Owl | D21: 4861 | E21: 猫头鹰 | G21: 11 | H21: ,
A22: 宗师 | B22: S | C22: Toroidion 1MW | D22: 4808 | E22: 1MW | F22: 能玩 | G22: 9 | H22: ,
A23: 宗师 | B23: S | C23: Mazzanti Evantra Millecavalli | D23: 4790 | E23: 皇后 | G23: 8 | H23: ,
A24: 宗师 | B24: S | C24: Inferno Automobili Inferno | D24: 4725 | E24: 地狱火 | G24: 6 | H24: ,
A25: 宗师 | B25: S | C25: SSC Ultimate Aero TT | D25: 4720 | E25: 老蜥蜴 | G25: 5 | H25: ,

Sheet 传奇
A1: 段位 | B1: 等级 | C1: 名称 | D1: 性能分 | E1: 昵称 | F1: 备注 | G1: 位置 | H1: 符号 | I1: 优先级
A2: 传奇 | B2: R | C2: Koenigsegg Jesko Absolut | D2: 5664 | E2: 杰皇 | F2: 综合霸主 | G2: 17 | H2: , | I2: 1 | J2: =G2&H2 -> 17, | L2: ▶ | M2: =_xlfn.CONCAT(J:J) -> 17,13,10,7,8,6,3,2,5,12,1,
A3: 传奇 | B3: R | C3: Bugatti Bolide | D3: 5385 | E3: 玻璃龙 | F3: 次霸 | G3: 13 | H3: , | I3: 2 | J3: =G3&H3 -> 13,
A4: 传奇 | B4: R | C4: Devel Sixteen | D4: 5254 | E4: 恶魔十六 | F4: 综合霸主 | G4: 10 | H4: , | I4: 3 | J4: =G4&H4 -> 10,
A5: 传奇 | B5: S | C5: Hennessey Venom F5 | D5: 5128 | E5: F5 | F5: 次霸 | G5: 7 | H5: , | I5: 4 | J5: =G5&H5 -> 7,
A6: 传奇 | B6: S | C6: Koenigsegg CC850 | D6: 5146 | E6: CC850 | F6: 能玩 | G6: 8 | H6: , | I6: 5 | J6: =G6&H6 -> 8,
A7: 传奇 | B7: S | C7: Zenvo Aurora Tur | D7: 5100 | E7: 自燃极光 | G7: 6 | H7: , | I7: 6 | J7: =G7&H7 -> 6,
A8: 传奇 | B8: S | C8: SSC Tuatara | D8: 4930 | E8: 大蜥蜴 | G8: 3 | H8: , | I8: 7 | J8: =G8&H8 -> 3,
A9: 传奇 | B9: S | C9: Koenigsegg Jesko | D9: 4824 | E9: 杰哥 | F9: 能玩 | G9: 2 | H9: , | I9: 8 | J9: =G9&H9 -> 2,
A10: 传奇 | B10: S | C10: Tushek Aeon E | D10: 5025 | E10: 爱音 | F10: 次霸 | G10: 5 | H10: , | I10: 9 | J10: =G10&H10 -> 5,
A11: 传奇 | B11: R | C11: Mercedes-Benz Silver Lightning | D11: 5344 | E11: 银电 | F11: 超级搅屎棍 | G11: 12 | H11: , | I11: 10 | J11: =G11&H11 -> 12,
A12: 传奇 | B12: S | C12: Bugatti Chiron | D12: 4755 | E12: 肥龙 | G12: 1 | H12: , | I12: 11 | J12: =G12&H12 -> 1,
A13: 传奇 | B13: R | C13: Hennessey Venom F5 Revolution | D13: 5656 | E13: F5R | F13: 综合霸主 | G13: 16 | H13: ,
A14: 传奇 | B14: R | C14: Rimac Nevera R | D14: 5611 | E14: 兔R | F14: 超级搅屎棍 | G14: 15 | H14: ,
A15: 传奇 | B15: R | C15: Bugatti Chiron Super Sport 300+ | D15: 5602 | E15: 300+ | G15: 14 | H15: ,
A16: 传奇 | B16: R | C16: SSC Tuatara Striker | D16: 5337 | E16: 小蜥蜴 | G16: 11 | H16: ,
A17: 传奇 | B17: S | C17: Mosler Super GT | D17: 5169 | E17: 莫斯勒 | F17: 能玩 | G17: 9 | H17: ,
A18: 传奇 | B18: S | C18: Koenigsegg Agera RS | D18: 4940 | E18: 阿格拉 | G18: 4 | H18: ,

Sheet 暂未显示
A1: 段位 | B1: 等级 | C1: 名称 | D1: 性能分 | E1: 昵称 | F1: 备注 | G1: 位置 | H1: 符号 | I1: 优先级

Sheet ！复制到脚本选车页
A1: 段位 | B1: 序号 | C1: 仅文本（左侧单元格去公式）
A2: 青铜 | B2: =青铜!M2 -> 34,35,33,32,29,22, | C2: 34,35,33,32,29,22,
A3: 白银 | B3: =白银!M2 -> 41,44,42,40,28,27,43,36, | C3: 29,45,41,44,42,40,28,27,43,36,
A4: 黄金 | B4: =黄金!M2 -> 41,39,36,16,45,26,32,25,31,23,42,44,28,10, | C4: 40,41,39,36,16,45,26,32,25,31,23,42,44,28,10,
A5: 白金 | B5: =白金!M2 -> 39,40,41,22,34,31,37,28,36,24,23,17,5,4,33, | C5: 39,40,41,22,34,31,37,28,36,24,23,17,5,4,33,
A6: 翡翠 | B6: =翡翠!M2 -> 31,32,33,17,30,29,26,22,20,16,15,14,13,12, | C6: 19,31,32,33,17,30,29,26,22,20,16,15,14,13,12,
A7: 钻石 | B7: =钻石!M2 -> 43,50,40,48,45,49,27,23,17,15,7,42,18,6,5,39,24,35,31,22,30,13,3,46,28, | C7: 43,50,40,48,45,49,27,23,17,15,7,42,18,6,5,39,24,35,31,22,30,13,3,46,28,
A8: 精英 | B8: =精英!M2 -> 37,25,34,14,33,36,13,38,11,31,29,30,9,26,6,19,18,17,16,20,10,7,5,2,12, | C8: 37,25,34,14,33,36,13,38,11,31,29,30,9,26,6,19,18,17,16,20,10,7,5,2,12,
A9: 宗师 | B9: =宗师!M2 -> 23,21,19,14,10,13,12,7,15,16,3,2,1,4, | C9: 23,21,19,14,10,13,12,7,15,16,3,2,1,4,
A10: 传奇 | B10: =传奇!M2 -> 17,13,10,7,8,6,3,2,5,12,1, | C10: 17,13,10,7,8,6,3,2,5,12,1,

Sheet 寻车工具车
A1: 级别 | B1: 1 | C1: 2 | D1: 3 | E1: 4 | F1: 5 | G1: 6 | H1: 7 | I1: 8 | J1: 9 | K1: 10
A2: C | B2: 莲花410 | C2: 道奇392 | D2: 911-黄 | E2: AMG GT | F2: 718 | G2: 小莲花 | H2: M4-黑 | I2: 野马-蓝 | J2: 911-蓝 | K2: 钥匙车
A3: B | B3: W70 | C3: 福特GT | D3: 白蛇 | E3: 罗马 | F3: 斯卡洛 | G3: GTR | H3: 玛莎-银 | I3: 剃刀 | J3: 钥匙车
A4: A | B4: 拉法 | C4: 003S | D4: 阿波罗N | E4: 百年牛 | F4: TDF | G4: 33 | H4: 蝙蝠 | I4: 钥匙车
A5: S | B5: 火山 | C5: 狼崽 | D5: 918 | E5: 毒药 | F5: 老捷豹 | G5: 自私 | H5: 蛙王 | I5: BC | J5: 电莲花
A6: 赛卡防错位
A7: 不重新选车
A8: 寻车序号
A9: 地图名
A10: C级顺序-7,6,8
A11: B级顺序-6,5,4
A12: A级顺序-5.4.3
A13: 通用顺序-6,5,4

Sheet 多人自选包
A1: 里程碑 | B1: 类型 | C1: 道具 | D1: 具体 | E1: 奖励序号 | F1: 逗号 | G1: 备注 | M1: 里程碑 | N1: 类型 | O1: 道具 | P1: 具体 | Q1: 奖励序号 | R1: 逗号 | S1: 备选
A2: 1000 | B2: 一般 | C2: 图纸 | E2: 4 | F2: , | H2: =E2&F2 -> 4, | J2: ▶ | K2: =_xlfn.CONCAT(H:H) -> 4,7,7,1,5,1,1,6,2, | M2: 600 | N2: 多通 | O2: 图纸 | Q2: 4 | R2: , | T2: =Q2&R2 -> 4, | V2: ▶ | W2: =_xlfn.CONCAT(T:T) -> 4,4,7,7,7,7,1,1,5,5,1,1,1,1,6,6,2,2,7,
A3: 3400 | B3: 一般 | C3: 图纸 | E3: 7 | F3: , | H3: =E3&F3 -> 7, | M3: 1000 | N3: 一般 | O3: 图纸 | Q3: 4 | R3: , | T3: =Q3&R3 -> 4,
A4: 6100 | B4: 一般 | C4: 图纸 | E4: 7 | F4: , | H4: =E4&F4 -> 7, | M4: 3000 | N4: 多通 | O4: 图纸 | Q4: 7 | R4: , | T4: =Q4&R4 -> 7,
A5: 8700 | B5: 一般 | C5: 图纸 | E5: 1 | F5: , | H5: =E5&F5 -> 1, | M5: 3400 | N5: 一般 | O5: 图纸 | Q5: 7 | R5: , | T5: =Q5&R5 -> 7, | V5: ▶ | W5: 4,4,7,7,7,7,1,1,5,5,1,1,1,1,6,6,2,2,1,
A6: 11500 | B6: 一般 | C6: 图纸 | E6: 5 | F6: , | G6: 7 | H6: =E6&F6 -> 5, | M6: 5700 | N6: 多通 | O6: 图纸 | Q6: 7 | R6: , | T6: =Q6&R6 -> 7,
A7: 15800 | B7: 一般 | C7: 图纸 | E7: 1 | F7: , | G7: 5 | H7: =E7&F7 -> 1, | M7: 6100 | N7: 一般 | O7: 图纸 | Q7: 7 | R7: , | T7: =Q7&R7 -> 7,
A8: 21100 | B8: 一般 | C8: 图纸 | E8: 1 | F8: , | H8: =E8&F8 -> 1, | M8: 8200 | N8: 多通 | O8: 图纸 | Q8: 1 | R8: , | T8: =Q8&R8 -> 1,
A9: 26400 | B9: 一般 | C9: 图纸 | E9: 6 | F9: , | G9: 1 | H9: =E9&F9 -> 6, | M9: 8700 | N9: 一般 | O9: 图纸 | Q9: 1 | R9: , | T9: =Q9&R9 -> 1,
A10: 31700 | B10: 一般 | C10: 图纸 | E10: 2 | F10: , | G10: 5 | H10: =E10&F10 -> 2, | M10: 11000 | N10: 多通 | O10: 图纸 | Q10: 5 | R10: , | S10: 7 | T10: =Q10&R10 -> 5,
M11: 11500 | N11: 一般 | O11: 图纸 | Q11: 5 | R11: , | S11: 7 | T11: =Q11&R11 -> 5,
M12: 14800 | N12: 多通 | O12: 图纸 | Q12: 1 | R12: , | S12: 5 | T12: =Q12&R12 -> 1,
M13: 15800 | N13: 一般 | O13: 图纸 | Q13: 1 | R13: , | S13: 5 | T13: =Q13&R13 -> 1,
M14: 20100 | N14: 多通 | O14: 图纸 | Q14: 1 | R14: , | T14: =Q14&R14 -> 1,
M15: 21100 | N15: 一般 | O15: 图纸 | Q15: 1 | R15: , | T15: =Q15&R15 -> 1,
M16: 25400 | N16: 多通 | O16: 图纸 | Q16: 6 | R16: , | S16: 1 | T16: =Q16&R16 -> 6,
M17: 26400 | N17: 一般 | O17: 图纸 | Q17: 6 | R17: , | S17: 1 | T17: =Q17&R17 -> 6,
M18: 30700 | N18: 多通 | O18: 图纸 | Q18: 2 | R18: , | S18: 5 | T18: =Q18&R18 -> 2,
M19: 31700 | N19: 一般 | O19: 图纸 | Q19: 2 | R19: , | S19: 5 | T19: =Q19&R19 -> 2,
M20: 34000 | N20: 多通 | O20: 车贴 | Q20: 7 | R20: , | S20: 2 | T20: =Q20&R20 -> 7,
AB25: ·

Sheet 待升级
A1: 段位 | B1: 等级 | C1: 名称 | D1: 性能分 | E1: 昵称 | F1: 备注 | G1: 优先级 | H1: 优先级
A2: 白金 | B2: A | C2: Ferrari 488 Challenge EVO | D2: 4095 | E2: 488 | F2: 综合霸主 | G2: 1
A3: 白银 | B3: B | C3: Lamborghini Huracan STO | D3: 3236 | E3: 牛STO | F3: 搅屎棍 | G3: 2
A4: 黄金 | B4: B | C4: Lamborghini Huracan Sterrato | D4: 3995 | E4: 越野牛 | F4: 综合霸主 | G4: 3
A5: 翡翠 | B5: A | C5: Lamborghini Aventador SVJ Roadster | D5: 4080 | E5: SVJ | F5: 综合霸主 | G5: 4
A6: 白金 | B6: B | C6: Lamborghini SC63 | D6: 4062 | E6: 牛-绿赛道 | F6: 能玩 | G6: 5
A7: 白金 | B7: B | C7: Formula E Gen 2 Asphalt Edition | D7: 4019 | E7: FE2 | F7: 能玩 | G7: 6
A8: 钻石 | B8: A | C8: Pagani Utopia Coupe | D8: 4308 | E8: 乌托邦 | F8: 能玩 | G8: 7
